Workbook

Sheet Instructions
A1: Instructions to get the drawdown notice file automated and shared to respective class of investors
A3: Steps | B3: Particulars
A4: =ROW()-3 -> 1 | B4: Based on working file the formats for drawdown is categorised and information needs to be incoroporated from working tab to respetive format tab in cells highlihgted in yellow
A5: =ROW()-3 -> 2 | B5: Client Name and address is to be added. Kindly ensure to give a letterhead format in the notice. You can add the following details: Nangia & Co LLP 4th Floor, Iconic Tower, URMI Estate, Ganpat Rao Kadam Marg, Lower Parel- 400013, India
A6: =ROW()-3 -> 3 | B6: Refer comments in Column G of "Format - Resident investors" for data flow from working tab
A7: =ROW()-3 -> 4 | B7: In "Format - LDC's" there is some additional informtaion to be provided so have added comments in those columns and can link it to working tab
A8: =ROW()-3 -> 5 | B8: Once data is filled in respctive formats, then PDF is required to be generated for all investors basis their format and classes.
A9: =ROW()-3 -> 6 | B9: Kindly convert the files and keep them ready to share emails to each investors after converting the notices in pdf format at one go. For emails to each investor, you can create a dummy email for each one of them and show that the mails are also shared with them

Sheet Working
A1: 1 | B1: =A1+1 -> 2 | C1: =B1+1 -> 3 | D1: =C1+1 -> 4 | E1: =D1+1 -> 5 | F1: =E1+1 -> 6 | G1: =F1+1 -> 7 | H1: =G1+1 -> 8 | I1: =H1+1 -> 9 | ... AL1: =AK1+1 -> 38
A2: Class | B2: Folio No. | C2: Class | D2: Close | E2: Formats for DD Notice | F2: Name of the contributor | G2: Address | H2: Email ID's | I2: Capital commitment | J2: Capital contributed till date | K2: Date for the 15th Drawdown | L2: 15th Drawdown Amount Called | M2: Capital contribution for Portfolio Investment (INR) | N2: Adjustment pursuant to previous drawdown (INR) | O2: Management fee till date (in INR) - Imputed Cost Adjustment | P2: Capital contribution for Management fees (INR) | Q2: Capital contribution for Establishment and Fund Expenses (INR) | R2: Adjustment for Interest Payable for FY 22 | S2: Adjustment for CC Payable for FY 22 | T2: Pending from previous contribution | U2: Excess Contribution | V2: Pending Pro-Rata | W2: 15th Drawdown Amount Payable | X2: 14th Drawdown Amount Paid | Y2: 13th Drawdown Amount Paid | Z2: 12th Drawdown Amount Paid | AA2: 11th Drawdown Amount Paid | AB2: 10th Drawdown Amount Paid | AC2: 9th Drawdown Amount Paid | AD2: 8th Drawdown Amount Paid | AE2: 7th Drawdown Amount Paid | AF2: 6th Drawdown Amount Paid | AG2: 5th Drawdown Amount Paid | AH2: 4th Drawdown Amount Paid | AI2: 3rd Drawdown Amount Paid | AJ2: 2nd Drawdown Amount Paid | AK2: 1st Drawdown Amount Paid | AL2: % on the Capital Commitment
A3: A1-001 | B3: A1-001 | C3: A1 | E3: Format - NRIs | I3: 12000000 | J3: =SUM(X3:AK3) -> 6508925 | K3: 46184 | L3: 699633 | M3: 625430.09 | N3: 0 | O3: 0 | P3: 60493.151 | Q3: 13709.762 | T3: 209877 | U3: 22948.9 | W3: =L3+T3-U3 -> 886561.1 | Y3: 478013 | Z3: 978334 | AA3: 436802 | AB3: 374359 | AC3: 1088971 | AD3: 399094 | AE3: 101137 | AF3: 779787 | AG3: 251916 | AH3: 412954 | AI3: 97115 | AJ3: 97942 | AK3: 1012501 | AL3: =(W3+J3+U3)/I3 -> 0.61820292
A4: A1-002 | B4: A1-002 | C4: A1 | E4: Format - NRIs | I4: 40000000 | J4: =SUM(X4:AK4) -> 22396010 | K4: 46184 | L4: 2332111 | M4: 2084767 | N4: 0 | O4: 0 | P4: 201643.84 | Q4: 45700.207 | W4: =L4+T4-U4 -> 2332111 | X4: 699590 | Y4: 1593377 | Z4: 3261113 | AA4: 1456018 | AB4: 1247860 | AC4: 3629904 | AD4: 1330311 | AE4: 337120 | AF4: 2599290 | AG4: 839720 | AH4: 1376513 | AI4: 323715 | AJ4: 326475 | AK4: 3375004 | AL4: =(W4+J4+U4)/I4 -> 0.61820303
A5: A1-003 | B5: A1-003 | C5: A1 | E5: Format - NRIs | I5: 10000000 | J5: =SUM(X5:AK5) -> 5599003 | K5: 46184 | L5: 583028 | M5: 521191.74 | N5: 0 | O5: 0 | P5: 50410.959 | Q5: 11425.302 | W5: =L5+T5-U5 -> 583028 | X5: 174897 | Y5: 398345 | Z5: 815279 | AA5: 364002 | AB5: 311966 | AC5: 907475 | AD5: 332577 | AE5: 84283 | AF5: 649822 | AG5: 209930 | AH5: 344128 | AI5: 80929 | AJ5: 81619 | AK5: 843751 | AL5: =(W5+J5+U5)/I5 -> 0.6182031
A6: A1-004 | B6: A1-004 | C6: A1 | E6: Format - NRIs | I6: 30000000 | J6: =SUM(X6:AK6) -> 16797010 | K6: 46184 | L6: 1749083 | M6: 1563575.2 | N6: 0 | O6: 0 | P6: 151232.88 | Q6: 34274.905 | W6: =L6+T6-U6 -> 1749083 | X6: 524692 | Y6: 1195033 | Z6: 2445836 | AA6: 1092015 | AB6: 935896 | AC6: 2722429 | AD6: 997732 | AE6: 252839 | AF6: 1949468 | AG6: 629790 | AH6: 1032385 | AI6: 242786 | AJ6: 244856 | AK6: 2531253 | AL6: =(W6+J6+U6)/I6 -> 0.6182031
A7: A1-005 | B7: A1-005 | C7: A1 | E7: Format - NRIs | I7: 20000000 | J7: =SUM(X7:AK7) -> 11198003 | K7: 46184 | L7: 1166055 | M7: 1042383.5 | N7: 0 | O7: 0 | P7: 100821.92 | Q7: 22849.603 | W7: =L7+T7-U7 -> 1166055 | X7: 349795 | Y7: 796688 | Z7: 1630556 | AA7: 728007 | AB7: 623930 | AC7: 1814953 | AD7: 665157 | AE7: 168559 | AF7: 1299644 | AG7: 419860 | AH7: 688257 | AI7: 161858 | AJ7: 163237 | AK7: 1687502 | AL7: =(W7+J7+U7)/I7 -> 0.6182029
A8: A1-006 | B8: A1-006 | C8: A1 | E8: Format - 2nd close NR inves | I8: 10000000 | J8: =SUM(X8:AK8) -> 5599003 | K8: 46184 | L8: 583028 | M8: 521191.74 | N8: 0 | O8: 0 | P8: 50410.959 | Q8: 11425.302 | W8: =L8+T8-U8 -> 583028 | X8: 174897 | Y8: 398345 | Z8: 815279 | AA8: 364002 | AB8: 311966 | AC8: 907475 | AD8: 332577 | AE8: 84205 | AF8: 2210257 | AL8: =(W8+J8+U8)/I8 -> 0.6182031
A9: A1-007 | B9: A1-007 | C9: A1 | E9: Format - 3rd close NR inves | I9: 100000000 | J9: =SUM(X9:AK9) -> 55990022 | K9: 46184 | L9: 5830278 | M9: 5211917.4 | N9: 0 | O9: 0 | P9: 504109.59 | Q9: 114251.02 | W9: =L9+T9-U9 -> 5830278 | X9: 1748974 | Y9: 3983442 | Z9: 8152784 | AA9: 3640043 | AB9: 3119652 | AC9: 9074762 | AD9: 3325593 | AE9: 22944772 | AL9: =(W9+J9+U9)/I9 -> 0.618203
A10: A2-001 | B10: A2-001 | C10: A2 | E10: Format - LDC's | I10: 1000000000 | J10: =SUM(X10:AK10) -> 550602644 | K10: 46184 | L10: 57546577 | M10: 52119174 | N10: 0 | O10: 0 | P10: 4284931.5 | Q10: 1142471.5 | W10: =L10+T10-U10 -> 57546577 | X10: 16741761 | Y10: 39086435 | Z10: 81527842 | AA10: 35193004 | AB10: 30448534 | AC10: 89758177 | AD10: 33473429 | AE10: 8165037 | AF10: 64226246 | AG10: 20236797 | AH10: 33664853 | AI10: 7327218 | AJ10: 7405612 | AK10: 83347699 | AL10: =(W10+J10+U10)/I10 -> 0.60814922
A11: A3-001 | B11: A3-001 | C11: A3 | E11: Format - Resident investors | I11: 20000000 | J11: =SUM(X11:AK11) -> 11198002 | K11: 46184 | L11: 1166055 | M11: 1042383.5 | N11: 0 | O11: 0 | P11: 100821.92 | Q11: 22849.603 | W11: =L11+T11-U11 -> 1166055 | X11: 349795 | Y11: 796688 | Z11: 1630556 | AA11: 4574483 | AB11: 311966 | AC11: 907475 | AD11: 332577 | AE11: 84283 | AF11: 649822 | AG11: 209930 | AH11: 344128 | AI11: 80929 | AJ11: 81619 | AK11: 843751 | AL11: =(W11+J11+U11)/I11 -> 0.61820285
A12: A3-002 | B12: A3-002 | C12: A3 | E12: Format - Resident investors | I12: 10000000 | J12: =SUM(X12:AK12) -> 5424106 | K12: 46184 | L12: 583028 | M12: 521191.74 | N12: 0 | O12: 0 | P12: 50410.959 | Q12: 11425.302 | T12: 174897 | W12: =L12+T12-U12 -> 757925 | Y12: 398345 | Z12: 815279 | AA12: 364002 | AB12: 311966 | AC12: 907475 | AD12: 332577 | AE12: 84283 | AF12: 649822 | AG12: 209930 | AH12: 344128 | AI12: 80929 | AJ12: 81619 | AK12: 843751 | AL12: =(W12+J12+U12)/I12 -> 0.6182031
A13: A3-003 | B13: A3-003 | C13: A3 | E13: Format - Resident investors | I13: 10000000 | J13: =SUM(X13:AK13) -> 5599003 | K13: 46184 | L13: 583028 | M13: 521191.74 | N13: 0 | O13: 0 | P13: 50410.959 | Q13: 11425.302 | W13: =L13+T13-U13 -> 583028 | X13: 174897 | Y13: 398345 | Z13: 815279 | AA13: 364002 | AB13: 311966 | AC13: 907475 | AD13: 332577 | AE13: 84283 | AF13: 649822 | AG13: 209930 | AH13: 344128 | AI13: 80929 | AJ13: 81619 | AK13: 843751 | AL13: =(W13+J13+U13)/I13 -> 0.6182031
A14: A3-004 | B14: A3-004 | C14: A3 | E14: Format - Resident investors | I14: 10000000 | J14: =SUM(X14:AK14) -> 5599003 | K14: 46184 | L14: 583028 | M14: 521191.74 | N14: 0 | O14: 0 | P14: 50410.959 | Q14: 11425.302 | U14: 648 | W14: =L14+T14-U14 -> 582380 | X14: 174897 | Y14: 398345 | Z14: 815279 | AA14: 364002 | AB14: 311966 | AC14: 907475 | AD14: 332577 | AE14: 84283 | AF14: 649822 | AG14: 209930 | AH14: 344128 | AI14: 80929 | AJ14: 81619 | AK14: 843751 | AL14: =(W14+J14+U14)/I14 -> 0.6182031
A15: A3-005 | B15: A3-005 | C15: A3 | E15: Format - Resident investors | I15: 10000000 | J15: =SUM(X15:AK15) -> 5599003 | K15: 46184 | L15: 583028 | M15: 521191.74 | N15: 0 | O15: 0 | P15: 50410.959 | Q15: 11425.302 | W15: =L15+T15-U15 -> 583028 | X15: 174897 | Y15: 398345 | Z15: 815279 | AA15: 364002 | AB15: 311966 | AC15: 907475 | AD15: 332577 | AE15: 84283 | AF15: 649822 | AG15: 209930 | AH15: 344128 | AI15: 80929 | AJ15: 81619 | AK15: 843751 | AL15: =(W15+J15+U15)/I15 -> 0.6182031
A16: A3-006 | B16: A3-006 | C16: A3 | E16: Format - Resident investors | I16: 20000000 | J16: =SUM(X16:AK16) -> 11198003 | K16: 46184 | L16: 1166055 | M16: 1042383.5 | N16: 0 | O16: 0 | P16: 100821.92 | Q16: 22849.603 | W16: =L16+T16-U16 -> 1166055 | X16: 349795 | Y16: 796688 | Z16: 1630556 | AA16: 728007 | AB16: 623930 | AC16: 1814953 | AD16: 665157 | AE16: 168559 | AF16: 1299644 | AG16: 419860 | AH16: 688257 | AI16: 161858 | AJ16: 163237 | AK16: 1687502 | AL16: =(W16+J16+U16)/I16 -> 0.6182029
A17: A3-007 | B17: A3-007 | C17: A3 | E17: Format - Resident investors | I17: 20000000 | J17: =SUM(X17:AK17) -> 11198003 | K17: 46184 | L17: 1166055 | M17: 1042383.5 | N17: 0 | O17: 0 | P17: 100821.92 | Q17: 22849.603 | W17: =L17+T17-U17 -> 1166055 | X17: 349795 | Y17: 796688 | Z17: 1630556 | AA17: 728007 | AB17: 623930 | AC17: 1814953 | AD17: 665157 | AE17: 168559 | AF17: 1299644 | AG17: 419860 | AH17: 688257 | AI17: 161858 | AJ17: 163237 | AK17: 1687502 | AL17: =(W17+J17+U17)/I17 -> 0.6182029
A18: A3-008 | B18: A3-008 | C18: A3 | E18: Format - Resident investors | I18: 30000000 | J18: =SUM(X18:AK18) -> 16797010 | K18: 46184 | L18: 1749083 | M18: 1563575.2 | N18: 0 | O18: 0 | P18: 151232.88 | Q18: 34274.905 | W18: =L18+T18-U18 -> 1749083 | X18: 524692 | Y18: 1195033 | Z18: 2445836 | AA18: 1092015 | AB18: 935896 | AC18: 2722429 | AD18: 997732 | AE18: 252839 | AF18: 1949468 | AG18: 629790 | AH18: 1032385 | AI18: 242786 | AJ18: 244856 | AK18: 2531253 | AL18: =(W18+J18+U18)/I18 -> 0.6182031
A19: A3-009 | B19: A3-009 | C19: A3 | E19: Format - Resident investors | I19: 10000000 | J19: =SUM(X19:AK19) -> 5599003 | K19: 46184 | L19: 583028 | M19: 521191.74 | N19: 0 | O19: 0 | P19: 50410.959 | Q19: 11425.302 | W19: =L19+T19-U19 -> 583028 | X19: 174897 | Y19: 398345 | Z19: 815279 | AA19: 364002 | AB19: 311966 | AC19: 907475 | AD19: 332577 | AE19: 84283 | AF19: 649822 | AG19: 209930 | AH19: 344128 | AI19: 80929 | AJ19: 81619 | AK19: 843751 | AL19: =(W19+J19+U19)/I19 -> 0.6182031
A20: A3-010 | B20: A3-010 | C20: A3 | E20: Format - Resident investors | I20: 10000000 | J20: =SUM(X20:AK20) -> 5599003 | K20: 46184 | L20: 583028 | M20: 521191.74 | N20: 0 | O20: 0 | P20: 50410.959 | Q20: 11425.302 | W20: =L20+T20-U20 -> 583028 | X20: 174897 | Y20: 398345 | Z20: 815279 | AA20: 364002 | AB20: 311966 | AC20: 907475 | AD20: 332577 | AE20: 84283 | AF20: 649822 | AG20: 209930 | AH20: 344128 | AI20: 80929 | AJ20: 81619 | AK20: 843751 | AL20: =(W20+J20+U20)/I20 -> 0.6182031
A21: A3-011 | B21: A3-011 | C21: A3 | E21: Format - Resident investors | I21: 30000000 | J21: =SUM(X21:AK21) -> 16797010 | K21: 46184 | L21: 1749083 | M21: 1563575.2 | N21: 0 | O21: 0 | P21: 151232.88 | Q21: 34274.905 | W21: =L21+T21-U21 -> 1749083 | X21: 524692 | Y21: 1195033 | Z21: 2445836 | AA21: 1092015 | AB21: 935896 | AC21: 2722429 | AD21: 997732 | AE21: 252839 | AF21: 1949468 | AG21: 629790 | AH21: 1032385 | AI21: 242786 | AJ21: 244856 | AK21: 2531253 | AL21: =(W21+J21+U21)/I21 -> 0.6182031
A22: A3-012 | B22: A3-012 | C22: A3 | E22: Format - Resident investors | I22: 100000000 | J22: =SUM(X22:AK22) -> 55990022 | K22: 46184 | L22: 5830278 | M22: 5211917.4 | N22: 0 | O22: 0 | P22: 504109.59 | Q22: 114251.02 | W22: =L22+T22-U22 -> 5830278 | X22: 1748974 | Y22: 3983442 | Z22: 8152784 | AA22: 3640043 | AB22: 3119652 | AC22: 9074762 | AD22: 3325773 | AE22: 842800 | AF22: 6498223 | AG22: 2099300 | AH22: 3441284 | AI22: 809288 | AJ22: 816187 | AK22: 8437510 | AL22: =(W22+J22+U22)/I22 -> 0.618203
A23: A3-013 | B23: A3-013 | C23: A3 | E23: Format - Resident investors | I23: 10000000 | J23: =SUM(X23:AK23) -> 5599003 | K23: 46184 | L23: 583028 | M23: 521191.74 | N23: 0 | O23: 0 | P23: 50410.959 | Q23: 11425.302 | W23: =L23+T23-U23 -> 583028 | X23: 174897 | Y23: 398345 | Z23: 815279 | AA23: 364002 | AB23: 311966 | AC23: 907475 | AD23: 332577 | AE23: 84283 | AF23: 649822 | AG23: 209930 | AH23: 344128 | AI23: 80929 | AJ23: 81619 | AK23: 843751 | AL23: =(W23+J23+U23)/I23 -> 0.6182031
A24: A3-014 | B24: A3-014 | C24: A3 | E24: Format - Resident investors | I24: 10000000 | J24: =SUM(X24:AK24) -> 5599003 | K24: 46184 | L24: 583028 | M24: 521191.74 | N24: 0 | O24: 0 | P24: 50410.959 | Q24: 11425.302 | W24: =L24+T24-U24 -> 583028 | X24: 174897 | Y24: 398345 | Z24: 815279 | AA24: 364002 | AB24: 311966 | AC24: 907475 | AD24: 332577 | AE24: 84283 | AF24: 649822 | AG24: 209930 | AH24: 344128 | AI24: 80929 | AJ24: 81619 | AK24: 843751 | AL24: =(W24+J24+U24)/I24 -> 0.6182031
A25: A3-015 | B25: A3-015 | C25: A3 | E25: Format - Resident investors | I25: 10000000 | J25: =SUM(X25:AK25) -> 5599003 | K25: 46184 | L25: 583028 | M25: 521191.74 | N25: 0 | O25: 0 | P25: 50410.959 | Q25: 11425.302 | W25: =L25+T25-U25 -> 583028 | X25: 174897 | Y25: 398345 | Z25: 815279 | AA25: 364002 | AB25: 311966 | AC25: 907475 | AD25: 332577 | AE25: 84283 | AF25: 649822 | AG25: 209930 | AH25: 344128 | AI25: 80929 | AJ25: 81619 | AK25: 843751 | AL25: =(W25+J25+U25)/I25 -> 0.6182031
A26: A3-016 | B26: A3-016 | C26: A3 | E26: Format - Resident investors | I26: 25000000 | J26: =SUM(X26:AK26) -> 13997506 | K26: 46184 | L26: 1457569 | M26: 1302979.3 | N26: 0 | O26: 0 | P26: 126027.4 | Q26: 28562.254 | W26: =L26+T26-U26 -> 1457569 | X26: 437244 | Y26: 995860 | Z26: 2038196 | AA26: 910012 | AB26: 779913 | AC26: 2268689 | AD26: 831442 | AE26: 210702 | AF26: 1624556 | AG26: 524825 | AH26: 860321 | AI26: 202322 | AJ26: 204047 | AK26: 2109377 | AL26: =(W26+J26+U26)/I26 -> 0.618203
... A37: A3-027 | B37: A3-027 | C37: A3 | E37: Format - Resident investors | I37: 10000000 | J37: =SUM(X37:AK37) -> 5599003 | K37: 46184 | L37: 583028 | M37: 521191.74 | N37: 0 | O37: 0 | P37: 50410.959 | Q37: 11425.302 | W37: =L37+T37-U37 -> 583028 | X37: 174897 | Y37: 398345 | Z37: 815279 | AA37: 364002 | AB37: 311966 | AC37: 907475 | AD37: 332577 | AE37: 84283 | AF37: 649822 | AG37: 209930 | AH37: 344128 | AI37: 80929 | AJ37: 81619 | AK37: 843751 | AL37: =(W37+J37+U37)/I37 -> 0.6182031
A38: A3-028 | B38: A3-028 | C38: A3 | E38: Format - Resident investors | I38: 10000000 | J38: =SUM(X38:AK38) -> 5599003 | K38: 46184 | L38: 583028 | M38: 521191.74 | N38: 0 | O38: 0 | P38: 50410.959 | Q38: 11425.302 | W38: =L38+T38-U38 -> 583028 | X38: 174897 | Y38: 398345 | Z38: 815279 | AA38: 364002 | AB38: 311966 | AC38: 907475 | AD38: 332577 | AE38: 84205 | AF38: 2210257 | AL38: =(W38+J38+U38)/I38 -> 0.6182031
A39: A3-029 | B39: A3-029 | C39: A3 | E39: Format - 2nd close R investors | I39: 20000000 | J39: =SUM(X39:AK39) -> 11198003 | K39: 46184 | L39: 1166055 | M39: 1042383.5 | N39: 0 | O39: 0 | P39: 100821.92 | Q39: 22849.603 | W39: =L39+T39-U39 -> 1166055 | X39: 349795 | Y39: 796688 | Z39: 1630556 | AA39: 728007 | AB39: 623930 | AC39: 1814953 | AD39: 665157 | AE39: 168403 | AF39: 4420514 | AL39: =(W39+J39+U39)/I39 -> 0.6182029
A40: A3-030 | B40: A3-030 | C40: A3 | E40: Format - 2nd close R investors | I40: 10000000 | J40: =SUM(X40:AK40) -> 5599003 | K40: 46184 | L40: 583028 | M40: 521191.74 | N40: 0 | O40: 0 | P40: 50410.959 | Q40: 11425.302 | W40: =L40+T40-U40 -> 583028 | X40: 174897 | Y40: 398345 | Z40: 815279 | AA40: 364002 | AB40: 311966 | AC40: 907475 | AD40: 332577 | AE40: 84205 | AF40: 2210257 | AL40: =(W40+J40+U40)/I40 -> 0.6182031
A41: A3-031 | B41: A3-031 | C41: A3 | E41: Format - 2nd close R investors | I41: 20000000 | J41: =SUM(X41:AK41) -> 11198002 | K41: 46184 | L41: 1166055 | M41: 1042383.5 | N41: 0 | O41: 0 | P41: 100821.92 | Q41: 22849.603 | W41: =L41+T41-U41 -> 1166055 | X41: 349795 | Y41: 796688 | Z41: 1630556 | AA41: 4574484 | AB41: 311966 | AC41: 907475 | AD41: 332559 | AE41: 2294479 | AL41: =(W41+J41+U41)/I41 -> 0.61820285
A42: A3-032 | B42: A3-032 | C42: A3 | E42: Format - 2nd close R investors | I42: 20000000 | J42: =SUM(X42:AK42) -> 11198003 | K42: 46184 | L42: 1166055 | M42: 1042383.5 | N42: 0 | O42: 0 | P42: 100821.92 | Q42: 22849.603 | W42: =L42+T42-U42 -> 1166055 | X42: 349795 | Y42: 796688 | Z42: 1630556 | AA42: 728007 | AB42: 623930 | AC42: 1814952 | AD42: 665122 | AE42: 4588953 | AL42: =(W42+J42+U42)/I42 -> 0.6182029
A43: A3-033 | B43: A3-033 | C43: A3 | E43: Format - 3rd close R invest | I43: 10000000 | J43: =SUM(X43:AK43) -> 5599003 | K43: 46184 | L43: 583028 | M43: 521191.74 | N43: 0 | O43: 0 | P43: 50410.959 | Q43: 11425.302 | W43: =L43+T43-U43 -> 583028 | X43: 174897 | Y43: 398345 | Z43: 815279 | AA43: 364003 | AB43: 311966 | AC43: 907475 | AD43: 332559 | AE43: 2294479 | AL43: =(W43+J43+U43)/I43 -> 0.6182031
A44: A3-035 | B44: A3-035 | C44: A3 | E44: Format - 3rd close R invest | I44: 10000000 | J44: =SUM(X44:AK44) -> 5599003 | K44: 46184 | L44: 583028 | M44: 521191.74 | N44: 0 | O44: 0 | P44: 50410.959 | Q44: 11425.302 | W44: =L44+T44-U44 -> 583028 | X44: 174897 | Y44: 398345 | Z44: 815279 | AA44: 364003 | AB44: 311966 | AC44: 907475 | AD44: 332559 | AE44: 2294479 | AL44: =(W44+J44+U44)/I44 -> 0.6182031
A45: A4-001 | B45: A4-001 | C45: A4 | E45: Format - LDC's | I45: 328820000 | J45: =SUM(X45:AK45) -> 182577776 | K45: 46184 | L45: 19046793 | M45: 17137827 | N45: 0 | O45: 0 | P45: 1533292.2 | Q45: 375674.06 | W45: =L45+T45-U45 -> 19046793 | X45: 5628001 | Y45: 12975377 | Z45: 26807985 | AA45: 11770682 | AB45: 10135063 | AC45: 29676957 | AD45: 10971270 | AE45: 2728058 | AF45: 21243167 | AG45: 6778591 | AH45: 11192653 | AI45: 2535218 | AJ45: 2559449 | AK45: 27575305 | AL45: =(W45+J45+U45)/I45 -> 0.61317611
A46: B1-001 | B46: B1-001 | C46: B1 | E46: Format - R Inv (Empl & Sponsor) | I46: 50000000 | J46: =SUM(X46:AK46) -> 24895813 | K46: 46184 | L46: 2663072 | M46: 2605958.7 | N46: 0 | O46: 0 | P46: 0 | Q46: 57113.303 | W46: =L46+T46-U46 -> 2663072 | X46: 625160 | Y46: 1742393 | Z46: 4076392 | AA46: 1417537 | AB46: 1310499 | AC46: 4207568 | AD46: 1734787 | AE46: 333746 | AF46: 2997112 | AG46: 797583 | AH46: 1471314 | AI46: =448274/3 -> 149424.67 | AJ46: =468026/3 -> 156008.67 | AK46: =11628867/3 -> 3876289 | AL46: =(W46+J46+U46)/I46 -> 0.55117771
A47: B2-001 | B47: B2-001 | C47: B2 | E47: Format - R Inv (Empl & Sponsor) | I47: 100000000 | J47: =SUM(X47:AK47) -> 49791631 | K47: 46184 | L47: 5326143 | M47: 5211917.4 | N47: 0 | O47: 0 | P47: 0 | Q47: 114225.61 | W47: =L47+T47-U47 -> 5326143 | X47: 1250319 | Y47: 3484787 | Z47: 8152784 | AA47: 2835076 | AB47: 2620997 | AC47: 8415138 | AD47: 3469574 | AE47: 667492 | AF47: 5994225 | AG47: 1595165 | AH47: 2942629 | AI47: =448274*2/3 -> 298849.33 | AJ47: =468026*2/3 -> 312017.33 | AK47: =11628867*2/3 -> 7752578 | AL47: =(W47+J47+U47)/I47 -> 0.55117774
A48: C-001 | B48: C-001 | C48: C | E48: Format - R Inv (Empl & Sponsor) | I48: 2500000 | J48: =SUM(X48:AK48) -> 1362352 | K48: 46184 | L48: 133154 | M48: 130297.93 | N48: 0 | O48: 0 | P48: 0 | Q48: 2856.0651 | W48: =L48+T48-U48 -> 133154 | X48: 31258 | Y48: 87120 | Z48: 203819 | AA48: 78535 | AB48: 77992 | AC48: 226868 | AD48: 83144 | AE48: 21071 | AF48: 162456 | AG48: 52482 | AH48: 86032 | AI48: 20232 | AJ48: 20405 | AK48: 210938 | AL48: =(W48+J48+U48)/I48 -> 0.5982024
A49: C-002 | B49: C-002 | C49: C | E49: Format - R Inv (Empl & Sponsor) | I49: 3500000 | J49: =SUM(X49:AK49) -> 1907292 | K49: 46184 | L49: 186415 | M49: 182417.11 | N49: 0 | O49: 0 | P49: 0 | Q49: 3997.8912 | W49: =L49+T49-U49 -> 186415 | X49: 43761 | Y49: 121967 | Z49: 285348 | AA49: 109948 | AB49: 109187 | AC49: 317617 | AD49: 116403 | AE49: 29498 | AF49: 227438 | AG49: 73475 | AH49: 120445 | AI49: 28325 | AJ49: 28567 | AK49: 295313 | AL49: =(W49+J49+U49)/I49 -> 0.598202
A50: C-003 | B50: C-003 | C50: C | E50: Format - R Inv (Empl & Sponsor) | I50: 2500000 | J50: =SUM(X50:AK50) -> 1362352 | K50: 46184 | L50: 133154 | M50: 130297.93 | N50: 0 | O50: 0 | P50: 0 | Q50: 2856.0651 | W50: =L50+T50-U50 -> 133154 | X50: 31258 | Y50: 87120 | Z50: 203819 | AA50: 78535 | AB50: 77992 | AC50: 226868 | AD50: 83144 | AE50: 21071 | AF50: 162456 | AG50: 52482 | AH50: 86032 | AI50: 20232 | AJ50: 20405 | AK50: 210938 | AL50: =(W50+J50+U50)/I50 -> 0.5982024
...

Sheet Format - Resident investors
G1: 46203 | H1: =TEXT(G1,"dd mmmm yyyy") -> 30 June 2026
G2: The payment towards capital contribution for the 15th drawdown is to be made in the bank account of XYZ FUND within 15 Business Days from the date of issue of this Drawdown Notice i.e. on or before
B3: CLIENT NAME AND ADDRESS
F4: Folio No | G4: C-007
G5: Input Client Name and address
A9: DRAWDOWN NOTICE
A10: =CONCATENATE("Class: ",Working!#REF!) -> #REF! | G10: reflects Class
A11: =CONCATENATE("Folio No.: ",Working!#REF!) -> #REF! | G11: reflects Folio No
A13: Date: 11 June 2026 | G13: Date to be changed
A15: To,
A16: =Working!#REF! -> #REF! | G16: Investor name
A17: =Working!#REF! -> #REF! | G17: Investor address
A19: Re: Notice of 15th Drawdown for XYZ FUND ('the Fund') | G19: Drawdown number to be changed
A21: Dear Investor,
A23: The undersigned refers to the Contribution Agreement dated May 26, 2023, (hereinafter referred to as the “Contribution Agreement”), and hereby gives you notice, pursuant to the Contribution Agreement, that the undersigned hereby requests the Drawdown, and in that connection sets forth below the information relating to such Drawdown as required under the Contribution Agreement.
A25: A summary of your capital commitment and contributions is given below:
A27: Capital commitment to XYZ FUND (INR) | B27: Capital contributed till date (INR) | C27: Capital contribution pursuant to the 15th Drawdown (INR) | D27: Capital contribution (after adjustment, if any) pursuant to the 15th Drawdown (INR) | E27: % of the Capital commitment drawn down till date | G27: Drawdown number to be changed Formula for Capital Contribution to be changed in working sheet
A28: Cloumn 9 of working tab | B28: Column 10 of working tab | C28: Column 12 of working tab | D28: Column 23 of working tab | E28: Column 38 of working tab | G28: Add information from working tab against each column
A30: The capital contribution for the current Drawdown will be applied towards portfolio investment in ABC Private Limited, Management Fees for the period 1st July 2026 to 30th September 2026 and Fund expenses. | G30: Date change for Management fees
A31: =G2&H1 -> The payment towards capital contribution for the 15th drawdown is to be made in the bank account of XYZ FUND within 15 Business Days from the date of issue of this Drawdown Notice i.e. on or before 30 June 2026 | G31: Drawdown number and due date to be changed
A34: Please instruct the remitting bank to transfer funds by wire transfer to the bank as mentioned below.
A36: Amount to be remitted (INR) | B36: =D28 -> Column 23 of working tab | G36: Check Formula
A37: Name of account holder | B37: XYZ FUND
A38: Bank Name & Branch
A39: Account type
A40: Account number
A41: IFSC Code
A42: SWIFT address
A44: Due to KYC norms being applicable for such investments, it is requested that the NEFT/RTGS instruction be issued from your designated bank account. Payment from third party accounts cannot be accepted.
B48: =B3 -> CLIENT NAME AND ADDRESS
G50: Input Client Name and address
A54: Once the payment is done, kindly inform us on our email id abc@gmail.com, the following details of your remittance as under: | G54: Add client email ID
A55: 1. Name of remitting bank and branch
A56: 2. Date of Remittance
A57: 3. Amount remitted
A58: 4. UTR No.
A60: Thank you in advance for your co-operation and attention to this matter.
A62: Yours truly,
A63: For ___________________LLP (On behalf of XYZ FUND)
A66: Sd/- Designated Partner

Sheet Format - R Inv (Empl & Sponsor)
B3: ='Format - Resident investors'!B3 -> CLIENT NAME AND ADDRESS
A9: DRAWDOWN NOTICE
A10: =CONCATENATE("Class: ",Working!#REF!) -> #REF!
A11: =CONCATENATE("Folio No.: ",Working!#REF!) -> #REF!
A13: ='Format - Resident investors'!A13 -> Date: 11 June 2026
A15: To,
A16: =Working!#REF! -> #REF!
A17: =Working!#REF! -> #REF!
A19: Re: Notice of 15th Drawdown for XYZ FUND ('the Fund')
A21: Dear Investor,
A23: The undersigned refers to the Contribution Agreement dated May 26, 2023, (hereinafter referred to as the “Contribution Agreement”), and hereby gives you notice, pursuant to the Contribution Agreement, that the undersigned hereby requests the Drawdown, and in that connection sets forth below the information relating to such Drawdown as required under the Contribution Agreement.
A25: A summary of your capital commitment and contributions is given below:
A27: ='Format - Resident investors'!A27 -> Capital commitment to XYZ FUND (INR) | B27: ='Format - Resident investors'!B27 -> Capital contributed till date (INR) | C27: ='Format - Resident investors'!C27 -> Capital contribution pursuant to the 15th Drawdown (INR) | D27: ='Format - Resident investors'!D27 -> Capital contribution (after adjustment, if any) pursuant to the 15th Drawdown (INR) | E27: ='Format - Resident investors'!E27 -> % of the Capital commitment drawn down till date
A28: =Working!#REF! -> #REF! | B28: =Working!#REF! -> #REF! | C28: =Working!#REF! -> #REF! | D28: =Working!#REF! -> #REF! | E28: =Working!#REF! -> #REF!
A30: The capital contribution for the current Drawdown will be applied towards portfolio investment in ABC Private Limited, Management Fees for the period 1st July 2026 to 30th September 2026 and Fund expenses.
A31: ='Format - Resident investors'!A31 -> The payment towards capital contribution for the 15th drawdown is to be made in the bank account of XYZ FUND within 15 Business Days from the date of issue of this Drawdown Notice i.e. on or before 30 June 2026
A34: Please instruct the remitting bank to transfer funds by wire transfer to the bank as mentioned below.
A36: Amount to be remitted (INR) | B36: =D28 -> #REF!
A37: Name of account holder | B37: XYZ FUND
A38: Bank Name & Branch
A39: Account type
A40: Account number
A41: IFSC Code
A42: SWIFT address
A44: Due to KYC norms being applicable for such investments, it is requested that the NEFT/RTGS instruction be issued from your designated bank account. Payment from third party accounts cannot be accepted.
B48: ='Format - Resident investors'!B3 -> CLIENT NAME AND ADDRESS
A54: ='Format - Resident investors'!A54 -> Once the payment is done, kindly inform us on our email id abc@gmail.com, the following details of your remittance as under:
A55: 1. Name of remitting bank and branch
A56: 2. Date of Remittance
A57: 3. Amount remitted
A58: 4. UTR No.
A60: Thank you in advance for your co-operation and attention to this matter.
A62: Yours truly,
A63: ='Format - Resident investors'!A63 -> For ___________________LLP (On behalf of XYZ FUND)
A66: Sd/- Designated Partner

Sheet Format - NRIs
B3: {='Format - R Inv (Empl & Sponsor)'!B3:D7} -> CLIENT NAME AND ADDRESS | C3: 0 | D3: 0
B4: 0 | C4: 0 | D4: 0
B5: 0 | C5: 0 | D5: 0
B6: 0 | C6: 0 | D6: 0
B7: 0 | C7: 0 | D7: 0
A9: DRAWDOWN NOTICE
A10: =CONCATENATE("Class: ",Working!#REF!) -> #REF!
A11: =CONCATENATE("Folio No.: ",Working!#REF!) -> #REF!
A13: ='Format - Resident investors'!A13 -> Date: 11 June 2026
A15: To,
A16: =Working!#REF! -> #REF!
A17: =Working!#REF! -> #REF!
A19: ='Format - Resident investors'!A19 -> Re: Notice of 15th Drawdown for XYZ FUND ('the Fund')
A21: Dear Investor,
A23: The undersigned refers to the Contribution Agreement dated May 26, 2023, (hereinafter referred to as the “Contribution Agreement”), and hereby gives you notice, pursuant to the Contribution Agreement, that the undersigned hereby requests the Drawdown, and in that connection sets forth below the information relating to such Drawdown as required under the Contribution Agreement.
A25: A summary of your capital commitment and contributions is given below:
A27: ='Format - Resident investors'!A27 -> Capital commitment to XYZ FUND (INR) | B27: ='Format - Resident investors'!B27 -> Capital contributed till date (INR) | C27: ='Format - Resident investors'!C27 -> Capital contribution pursuant to the 15th Drawdown (INR) | D27: ='Format - Resident investors'!D27 -> Capital contribution (after adjustment, if any) pursuant to the 15th Drawdown (INR) | E27: ='Format - Resident investors'!E27 -> % of the Capital commitment drawn down till date
A28: =Working!#REF! -> #REF! | B28: =Working!#REF! -> #REF! | C28: =Working!#REF! -> #REF! | D28: =Working!#REF! -> #REF! | E28: =Working!#REF! -> #REF!
A30: ='Format - Resident investors'!A30 -> The capital contribution for the current Drawdown will be applied towards portfolio investment in ABC Private Limited, Management Fees for the period 1st July 2026 to 30th September 2026 and Fund expenses.
A31: ='Format - Resident investors'!A31 -> The payment towards capital contribution for the 15th drawdown is to be made in the bank account of XYZ FUND within 15 Business Days from the date of issue of this Drawdown Notice i.e. on or before 30 June 2026
A34: Please instruct the remitting bank to transfer funds by wire transfer to the bank as mentioned below.
A36: Amount to be remitted (INR) | B36: =D28 -> #REF!
A37: Name of account holder | B37: XYZ FUND
A38: Bank Name & Branch
A39: Account type
A40: Account number
A41: IFSC Code
A42: SWIFT address
A44: For International remittances, please find below USD account details
A46: Correspondent Bank: Correspondent Bank SWIFT CODE: Correspondent Bank Account number: Beneficiary Bank Account number:
B50: {='Format - R Inv (Empl & Sponsor)'!B48:D50} -> CLIENT NAME AND ADDRESS | C50: 0 | D50: 0
B51: 0 | C51: 0 | D51: 0
B52: 0 | C52: 0 | D52: 0
A57: Due to KYC norms being applicable for such investments, it is requested that the NEFT/RTGS instruction be issued from your designated bank account. Payment from third party accounts cannot be accepted.
A60: ='Format - R Inv (Empl & Sponsor)'!A54 -> Once the payment is done, kindly inform us on our email id abc@gmail.com, the following details of your remittance as under:
A61: 1. Name of remitting bank and branch
A62: 2. Date of Remittance
A63: 3. Amount remitted
A64: 4. UTR No.
A66: Thank you in advance for your co-operation and attention to this matter.
...

Sheet Format - LDC's
B3: ='Format - NRIs'!B3 -> CLIENT NAME AND ADDRESS
A9: DRAWDOWN NOTICE
A10: =CONCATENATE("Class: ",Working!#REF!) -> #REF!
A11: =CONCATENATE("Class: ",Working!#REF!) -> #REF!
A13: ='Format - Resident investors'!A13 -> Date: 11 June 2026
A15: To,
A16: =Working!#REF! -> #REF!
A17: =Working!#REF! -> #REF!
A19: ='Format - Resident investors'!A19 -> Re: Notice of 15th Drawdown for XYZ FUND ('the Fund')
A21: Dear Investor,
A23: The undersigned refers to the Contribution Agreement dated May 26, 2023, (hereinafter referred to as the “Contribution Agreement”), and hereby gives you notice, pursuant to the Contribution Agreement, that the undersigned hereby requests the Drawdown, and in that connection sets forth below the information relating to such Drawdown as required under the Contribution Agreement.
A25: A summary of your capital commitment and contributions is given below:
A27: ='Format - Resident investors'!A27 -> Capital commitment to XYZ FUND (INR) | B27: ='Format - Resident investors'!B27 -> Capital contributed till date (INR) | C27: ='Format - Resident investors'!C27 -> Capital contribution pursuant to the 15th Drawdown (INR) | D27: Adjustment pursuant to previous drawdown (INR) | E27: Total capital contribution pursuant to the 15th Drawdown (INR) | F27: ='Format - Resident investors'!E27 -> % of the Capital commitment drawn down till date
A28: =Working!#REF! -> #REF! | B28: =Working!#REF! -> #REF! | C28: =Working!#REF! -> #REF! | D28: Column 14 of working tab | E28: =Working!#REF! -> #REF! | F28: =Working!#REF! -> #REF!
A30: ='Format - Resident investors'!A30 -> The capital contribution for the current Drawdown will be applied towards portfolio investment in ABC Private Limited, Management Fees for the period 1st July 2026 to 30th September 2026 and Fund expenses.
A32: Capital contribution for Portfolio Investment (INR) | C32: Capital contribution for Management fees (INR) | E32: Capital contribution for Fund Expenses (INR) | G32: =A33+E33+C33-C28 -> #VALUE!
A33: Column 13 of working tab | C33: Column 16 of working tab | E33: Column 17 of working tab | G33: =A33+E33+C33 -> #VALUE!
A35: ='Format - Resident investors'!A31 -> The payment towards capital contribution for the 15th drawdown is to be made in the bank account of XYZ FUND within 15 Business Days from the date of issue of this Drawdown Notice i.e. on or before 30 June 2026
A38: Please instruct the remitting bank to transfer funds by wire transfer to the bank as mentioned below.
A40: Amount to be remitted (INR) | B40: =E28 -> #REF!
A41: Name of account holder | B41: XYZ FUND
A42: Bank Name & Branch
A43: Account type
A44: Account number
A45: IFSC Code
A46: SWIFT address
B52: ='Format - NRIs'!B50 -> CLIENT NAME AND ADDRESS
A58: Due to KYC norms being applicable for such investments, it is requested that the NEFT/RTGS instruction be issued from your designated bank account. Payment from third party accounts cannot be accepted.
A61: ='Format - NRIs'!A60 -> Once the payment is done, kindly inform us on our email id abc@gmail.com, the following details of your remittance as under:
A62: 1. Name of remitting bank and branch
A63: 2. Date of Remittance
A64: 3. Amount remitted
A65: 4. UTR No.
A67: Thank you in advance for your co-operation and attention to this matter.
A69: Yours truly,
A70: ='Format - NRIs'!A69 -> For ___________________LLP (On behalf of XYZ FUND)
A73: ='Format - NRIs'!A72 -> Sd/- Designated Partner

Sheet Format - 2nd close R investors
B3: {=_xlfn.ANCHORARRAY('Format - LDC''s'!B3)} -> CLIENT NAME AND ADDRESS | C3: 0 | D3: 0
B4: 0 | C4: 0 | D4: 0
B5: 0 | C5: 0 | D5: 0
B6: 0 | C6: 0 | D6: 0
B7: 0 | C7: 0 | D7: 0
A9: DRAWDOWN NOTICE
A10: =CONCATENATE("Class: ",Working!#REF!) -> #REF!
A11: =CONCATENATE("Folio No.: ",Working!#REF!) -> #REF!
A13: ='Format - Resident investors'!A13 -> Date: 11 June 2026
A15: To,
A16: =Working!#REF! -> #REF!
A17: =Working!#REF! -> #REF!
A19: ='Format - Resident investors'!A19 -> Re: Notice of 15th Drawdown for XYZ FUND ('the Fund')
A21: Dear Investor,
A23: The undersigned refers to the Contribution Agreement dated August 30, 2024, (hereinafter referred to as the “Contribution Agreement”), and hereby gives you notice, pursuant to the Contribution Agreement, that the undersigned hereby requests the Drawdown, and in that connection sets forth below the information relating to such Drawdown as required under the Contribution Agreement.
A25: A summary of your capital commitment and contributions is given below:
A27: Capital commitment to XYZ FUND (INR) | B27: Capital contributed till date (INR) | C27: ='Format - Resident investors'!C27 -> Capital contribution pursuant to the 15th Drawdown (INR) | D27: ='Format - Resident investors'!D27 -> Capital contribution (after adjustment, if any) pursuant to the 15th Drawdown (INR) | E27: % of the Capital commitment drawn down till date
A28: =Working!#REF! -> #REF! | B28: =Working!#REF! -> #REF! | C28: =Working!#REF! -> #REF! | D28: =Working!#REF! -> #REF! | E28: =Working!#REF! -> #REF!
A30: ='Format - Resident investors'!A30 -> The capital contribution for the current Drawdown will be applied towards portfolio investment in ABC Private Limited, Management Fees for the period 1st July 2026 to 30th September 2026 and Fund expenses.
A31: ='Format - Resident investors'!A31 -> The payment towards capital contribution for the 15th drawdown is to be made in the bank account of XYZ FUND within 15 Business Days from the date of issue of this Drawdown Notice i.e. on or before 30 June 2026
A34: Please instruct the remitting bank to transfer funds by wire transfer to the bank as mentioned below.
A36: Amount to be remitted (INR) | B36: =D28 -> #REF!
A37: Name of account holder | B37: XYZ FUND
A38: Bank Name & Branch
A39: Account type
A40: Account number
A41: IFSC Code
A42: SWIFT address
A44: Due to KYC norms being applicable for such investments, it is requested that the NEFT/RTGS instruction be issued from your designated bank account. Payment from third party accounts cannot be accepted.
B48: {='Format - LDC''s'!B52:D54} -> CLIENT NAME AND ADDRESS | C48: 0 | D48: 0
B49: 0 | C49: 0 | D49: 0
B50: 0 | C50: 0 | D50: 0
A54: {='Format - LDC''s'!A61:F61} -> Once the payment is done, kindly inform us on our email id abc@gmail.com, the following details of your remittance as under: | B54: 0 | C54: 0 | D54: 0 | E54: 0 | F54: 0
A55: 1. Name of remitting bank and branch
A56: 2. Date of Remittance
A57: 3. Amount remitted
A58: 4. UTR No.
A60: Thank you in advance for your co-operation and attention to this matter.
A62: Yours truly,
A63: ='Format - LDC''s'!A70 -> For ___________________LLP (On behalf of XYZ FUND)
...

Sheet Format - 2nd close NR investors
B3: ='Format - 2nd close R investors'!B3 -> CLIENT NAME AND ADDRESS | C3: 0 | D3: 0
B4: 0 | C4: 0 | D4: 0
B5: 0 | C5: 0 | D5: 0
B6: 0 | C6: 0 | D6: 0
B7: 0 | C7: 0 | D7: 0
A9: DRAWDOWN NOTICE
A10: =CONCATENATE("Class: ",Working!#REF!) -> #REF!
A11: =CONCATENATE("Folio No.: ",Working!#REF!) -> #REF!
A13: ='Format - Resident investors'!A13 -> Date: 11 June 2026
A15: To,
A16: =Working!#REF! -> #REF!
A17: =Working!#REF! -> #REF!
A19: ='Format - Resident investors'!A19 -> Re: Notice of 15th Drawdown for XYZ FUND ('the Fund')
A21: Dear Investor,
A23: The undersigned refers to the Contribution Agreement dated August 30, 2024, (hereinafter referred to as the “Contribution Agreement”), and hereby gives you notice, pursuant to the Contribution Agreement, that the undersigned hereby requests the Drawdown, and in that connection sets forth below the information relating to such Drawdown as required under the Contribution Agreement.
A25: A summary of your capital commitment and contributions is given below:
A27: ='Format - Resident investors'!A27 -> Capital commitment to XYZ FUND (INR) | B27: ='Format - Resident investors'!B27 -> Capital contributed till date (INR) | C27: ='Format - Resident investors'!C27 -> Capital contribution pursuant to the 15th Drawdown (INR) | D27: ='Format - Resident investors'!D27 -> Capital contribution (after adjustment, if any) pursuant to the 15th Drawdown (INR) | E27: ='Format - Resident investors'!E27 -> % of the Capital commitment drawn down till date
A28: =Working!#REF! -> #REF! | B28: =Working!#REF! -> #REF! | C28: =Working!#REF! -> #REF! | D28: =Working!#REF! -> #REF! | E28: =Working!#REF! -> #REF!
A30: ='Format - Resident investors'!A30 -> The capital contribution for the current Drawdown will be applied towards portfolio investment in ABC Private Limited, Management Fees for the period 1st July 2026 to 30th September 2026 and Fund expenses.
A31: ='Format - Resident investors'!A31 -> The payment towards capital contribution for the 15th drawdown is to be made in the bank account of XYZ FUND within 15 Business Days from the date of issue of this Drawdown Notice i.e. on or before 30 June 2026
A32: ='Format - Resident investors'!A32 -> 0
A34: Please instruct the remitting bank to transfer funds by wire transfer to the bank as mentioned below.
A36: Amount to be remitted (INR) | B36: =D28 -> #REF!
A37: Name of account holder | B37: XYZ FUND
A38: Bank Name & Branch
A39: Account type
A40: Account number
A41: IFSC Code
A42: SWIFT address
A44: For International remittances, please find below USD account details
A46: Correspondent Bank: Correspondent Bank SWIFT CODE: Correspondent Bank Account number: Beneficiary Bank Account number:
B50: =B3 -> CLIENT NAME AND ADDRESS
A57: Due to KYC norms being applicable for such investments, it is requested that the NEFT/RTGS instruction be issued from your designated bank account. Payment from third party accounts cannot be accepted.
A60: Once the payment is done, kindly inform us on our email id abc@gmail.com, the following details of your remittance as under:
A61: 1. Name of remitting bank and branch
A62: 2. Date of Remittance
A63: 3. Amount remitted
A64: 4. UTR No.
A66: Thank you in advance for your co-operation and attention to this matter.
A68: Yours truly,
...

Sheet Format - 3rd close NR inves
B3: ='Format - 2nd close NR investors'!B50 -> CLIENT NAME AND ADDRESS
A9: DRAWDOWN NOTICE
A10: =CONCATENATE("Class: ",Working!#REF!) -> #REF!
A11: =CONCATENATE("Folio No.: ",Working!#REF!) -> #REF!
A13: ='Format - Resident investors'!A13 -> Date: 11 June 2026
A15: To,
A16: =Working!#REF! -> #REF!
A17: =Working!#REF! -> #REF!
A19: ='Format - Resident investors'!A19 -> Re: Notice of 15th Drawdown for XYZ FUND ('the Fund') | B19: ='Format - Resident investors'!B19 -> 0 | C19: ='Format - Resident investors'!C19 -> 0 | D19: ='Format - Resident investors'!D19 -> 0 | E19: ='Format - Resident investors'!E19 -> 0
A21: Dear Investor,
A23: The undersigned refers to the Contribution Agreement dated January 10, 2025, (hereinafter referred to as the “Contribution Agreement”), and hereby gives you notice, pursuant to the Contribution Agreement, that the undersigned hereby requests the Drawdown, and in that connection sets forth below the information relating to such Drawdown as required under the Contribution Agreement.
A25: A summary of your capital commitment and contributions is given below:
A27: ='Format - Resident investors'!A27 -> Capital commitment to XYZ FUND (INR) | B27: ='Format - Resident investors'!B27 -> Capital contributed till date (INR) | C27: ='Format - Resident investors'!C27 -> Capital contribution pursuant to the 15th Drawdown (INR) | D27: ='Format - Resident investors'!D27 -> Capital contribution (after adjustment, if any) pursuant to the 15th Drawdown (INR) | E27: ='Format - Resident investors'!E27 -> % of the Capital commitment drawn down till date
A28: =Working!#REF! -> #REF! | B28: =Working!#REF! -> #REF! | C28: =Working!#REF! -> #REF! | D28: =Working!#REF! -> #REF! | E28: =Working!#REF! -> #REF!
A30: ='Format - Resident investors'!A30 -> The capital contribution for the current Drawdown will be applied towards portfolio investment in ABC Private Limited, Management Fees for the period 1st July 2026 to 30th September 2026 and Fund expenses. | B30: ='Format - Resident investors'!B30 -> 0 | C30: ='Format - Resident investors'!C30 -> 0 | D30: ='Format - Resident investors'!D30 -> 0 | E30: ='Format - Resident investors'!E30 -> 0
A31: ='Format - Resident investors'!A31 -> The payment towards capital contribution for the 15th drawdown is to be made in the bank account of XYZ FUND within 15 Business Days from the date of issue of this Drawdown Notice i.e. on or before 30 June 2026 | B31: ='Format - Resident investors'!B31 -> 0 | C31: ='Format - Resident investors'!C31 -> 0 | D31: ='Format - Resident investors'!D31 -> 0 | E31: ='Format - Resident investors'!E31 -> 0
A32: ='Format - Resident investors'!A32 -> 0 | B32: ='Format - Resident investors'!B32 -> 0 | C32: ='Format - Resident investors'!C32 -> 0 | D32: ='Format - Resident investors'!D32 -> 0 | E32: ='Format - Resident investors'!E32 -> 0
A34: Please instruct the remitting bank to transfer funds by wire transfer to the bank as mentioned below.
A36: Amount to be remitted (INR) | B36: =D28 -> #REF!
A37: Name of account holder | B37: XYZ FUND
A38: Bank Name & Branch
A39: Account type
A40: Account number
A41: IFSC Code
A42: SWIFT address
A44: For International remittances, please find below USD account details
A46: Correspondent Bank: Correspondent Bank SWIFT CODE: Correspondent Bank Account number: Beneficiary Bank Account number:
B50: =B3 -> CLIENT NAME AND ADDRESS
A57: Due to KYC norms being applicable for such investments, it is requested that the NEFT/RTGS instruction be issued from your designated bank account. Payment from third party accounts cannot be accepted.
A60: Once the payment is done, kindly inform us on our email id abc@gmail.com, the following details of your remittance as under:
A61: 1. Name of remitting bank and branch
A62: 2. Date of Remittance
A63: 3. Amount remitted
A64: 4. UTR No.
A66: Thank you in advance for your co-operation and attention to this matter.
A68: Yours truly,
A69: ='Format - 2nd close NR investors'!A69 -> For ___________________LLP (On behalf of XYZ FUND)
A72: ='Format - 2nd close NR investors'!A72 -> Sd/- Designated Partner

Sheet Format - 3rd close R invest
B3: ='Format - 3rd close NR inves'!B3 -> CLIENT NAME AND ADDRESS
A9: DRAWDOWN NOTICE
A10: =CONCATENATE("Class: ",Working!#REF!) -> #REF!
A11: =CONCATENATE("Folio No.: ",Working!#REF!) -> #REF!
A13: ='Format - 3rd close NR inves'!A13 -> Date: 11 June 2026
A15: To,
A16: =Working!#REF! -> #REF!
A17: =Working!#REF! -> #REF!
A18: ='Format - Resident investors'!A19 -> Re: Notice of 15th Drawdown for XYZ FUND ('the Fund') | B18: ='Format - 3rd close NR inves'!B18 -> 0 | C18: ='Format - 3rd close NR inves'!C18 -> 0 | D18: ='Format - 3rd close NR inves'!D18 -> 0 | E18: ='Format - 3rd close NR inves'!E18 -> 0
A20: Dear Investor,
A22: The undersigned refers to the Contribution Agreement dated January 10, 2025 (hereinafter referred to as the “Contribution Agreement”), and hereby gives you notice, pursuant to the Contribution Agreement, that the undersigned hereby requests the Drawdown, and in that connection sets forth below the information relating to such Drawdown as required under the Contribution Agreement.
A24: A summary of your capital commitment and contributions is given below:
A26: Capital commitment to XYZ FUND (INR) | B26: Capital contributed till date (INR) | C26: ='Format - Resident investors'!C27 -> Capital contribution pursuant to the 15th Drawdown (INR) | D26: ='Format - Resident investors'!D27 -> Capital contribution (after adjustment, if any) pursuant to the 15th Drawdown (INR) | E26: % of the Capital commitment drawn down till date
A27: =Working!#REF! -> #REF! | B27: =Working!#REF! -> #REF! | C27: =Working!#REF! -> #REF! | D27: =Working!#REF! -> #REF! | E27: =Working!#REF! -> #REF!
A29: ='Format - Resident investors'!A30 -> The capital contribution for the current Drawdown will be applied towards portfolio investment in ABC Private Limited, Management Fees for the period 1st July 2026 to 30th September 2026 and Fund expenses. | B29: ='Format - 3rd close NR inves'!B29 -> 0 | C29: ='Format - 3rd close NR inves'!C29 -> 0 | D29: ='Format - 3rd close NR inves'!D29 -> 0 | E29: ='Format - 3rd close NR inves'!E29 -> 0
A30: ='Format - Resident investors'!A31 -> The payment towards capital contribution for the 15th drawdown is to be made in the bank account of XYZ FUND within 15 Business Days from the date of issue of this Drawdown Notice i.e. on or before 30 June 2026 | B30: ='Format - 3rd close NR inves'!B30 -> 0 | C30: ='Format - 3rd close NR inves'!C30 -> 0 | D30: ='Format - 3rd close NR inves'!D30 -> 0 | E30: ='Format - 3rd close NR inves'!E30 -> 0
A31: ='Format - Resident investors'!A32 -> 0 | B31: ='Format - 3rd close NR inves'!B31 -> 0 | C31: ='Format - 3rd close NR inves'!C31 -> 0 | D31: ='Format - 3rd close NR inves'!D31 -> 0 | E31: ='Format - 3rd close NR inves'!E31 -> 0
A33: Please instruct the remitting bank to transfer funds by wire transfer to the bank as mentioned below.
A35: Amount to be remitted (INR) | B35: =D27 -> #REF!
A36: Name of account holder | B36: XYZ FUND
A37: Bank Name & Branch
A38: Account type
A39: Account number
A40: IFSC Code
A41: SWIFT address
A43: Due to KYC norms being applicable for such investments, it is requested that the NEFT/RTGS instruction be issued from your designated bank account. Payment from third party accounts cannot be accepted.
B47: =B3 -> CLIENT NAME AND ADDRESS
A53: Once the payment is done, kindly inform us on our email id abc@gmail.com, the following details of your remittance as under:
A54: 1. Name of remitting bank and branch
A55: 2. Date of Remittance
A56: 3. Amount remitted
A57: 4. UTR No.
A59: Thank you in advance for your co-operation and attention to this matter.
A61: Yours truly,
A62: ='Format - 3rd close NR inves'!A69 -> For ___________________LLP (On behalf of XYZ FUND)
A65: ='Format - 3rd close NR inves'!A72 -> Sd/- Designated Partner

Sheet Format - Final close Employee
B3: ='Format - 3rd close R invest'!B3 -> CLIENT NAME AND ADDRESS
A9: DRAWDOWN NOTICE
A10: =CONCATENATE("Class: ",Working!#REF!) -> #REF!
A11: =CONCATENATE("Folio No.: ",Working!#REF!) -> #REF!
A13: ='Format - 3rd close NR inves'!A13 -> Date: 11 June 2026
A15: To,
A16: =Working!#REF! -> #REF!
A17: =Working!#REF! -> #REF!
A18: ='Format - Resident investors'!A19 -> Re: Notice of 15th Drawdown for XYZ FUND ('the Fund') | B18: ='Format - 3rd close NR inves'!B18 -> 0 | C18: ='Format - 3rd close NR inves'!C18 -> 0 | D18: ='Format - 3rd close NR inves'!D18 -> 0 | E18: ='Format - 3rd close NR inves'!E18 -> 0
A20: Dear Investor,
A22: The undersigned refers to the Contribution Agreement dated September 30, 2025 (hereinafter referred to as the “Contribution Agreement”), and hereby gives you notice, pursuant to the Contribution Agreement, that the undersigned hereby requests the Drawdown, and in that connection sets forth below the information relating to such Drawdown as required under the Contribution Agreement.
A24: A summary of your capital commitment and contributions is given below:
A26: Capital commitment to XYZ FUND (INR) | B26: Capital contributed till date (INR) | C26: ='Format - Resident investors'!C27 -> Capital contribution pursuant to the 15th Drawdown (INR) | D26: ='Format - Resident investors'!D27 -> Capital contribution (after adjustment, if any) pursuant to the 15th Drawdown (INR) | E26: % of the Capital commitment drawn down till date
A27: =Working!#REF! -> #REF! | B27: =Working!#REF! -> #REF! | C27: =Working!#REF! -> #REF! | D27: =Working!#REF! -> #REF! | E27: =Working!#REF! -> #REF!
A29: The capital contribution for the current Drawdown will be applied towards portfolio investment in ABC Private Limited and Fund expenses. | B29: ='Format - 3rd close NR inves'!B29 -> 0 | C29: ='Format - 3rd close NR inves'!C29 -> 0 | D29: ='Format - 3rd close NR inves'!D29 -> 0 | E29: ='Format - 3rd close NR inves'!E29 -> 0
A30: ='Format - Resident investors'!A31 -> The payment towards capital contribution for the 15th drawdown is to be made in the bank account of XYZ FUND within 15 Business Days from the date of issue of this Drawdown Notice i.e. on or before 30 June 2026 | B30: ='Format - 3rd close NR inves'!B30 -> 0 | C30: ='Format - 3rd close NR inves'!C30 -> 0 | D30: ='Format - 3rd close NR inves'!D30 -> 0 | E30: ='Format - 3rd close NR inves'!E30 -> 0
A31: ='Format - Resident investors'!A32 -> 0 | B31: ='Format - 3rd close NR inves'!B31 -> 0 | C31: ='Format - 3rd close NR inves'!C31 -> 0 | D31: ='Format - 3rd close NR inves'!D31 -> 0 | E31: ='Format - 3rd close NR inves'!E31 -> 0
A33: Please instruct the remitting bank to transfer funds by wire transfer to the bank as mentioned below.
A35: Amount to be remitted (INR) | B35: =D27 -> #REF!
A36: Name of account holder | B36: XYZ FUND
A37: Bank Name & Branch
A38: Account type
A39: Account number
A40: IFSC Code
A41: SWIFT address
A43: Due to KYC norms being applicable for such investments, it is requested that the NEFT/RTGS instruction be issued from your designated bank account. Payment from third party accounts cannot be accepted.
B47: =B3 -> CLIENT NAME AND ADDRESS
A53: Once the payment is done, kindly inform us on our email id abc@gmail.com, the following details of your remittance as under:
A54: 1. Name of remitting bank and branch
A55: 2. Date of Remittance
A56: 3. Amount remitted
A57: 4. UTR No.
A59: Thank you in advance for your co-operation and attention to this matter.
A61: Yours truly,
A62: ='Format - 3rd close R invest'!A62 -> For ___________________LLP (On behalf of XYZ FUND)
A65: ='Format - 3rd close R invest'!A65 -> Sd/- Designated Partner

Sheet Format - Institutional Inv
B3: ='Format - Final close Employee'!B3 -> CLIENT NAME AND ADDRESS
A9: DRAWDOWN NOTICE
A10: =CONCATENATE("Class: ",Working!#REF!) -> #REF!
A11: =CONCATENATE("Folio No.: ",Working!#REF!) -> #REF!
A13: ='Format - Resident investors'!A13 -> Date: 11 June 2026
A15: To,
A16: =Working!#REF! -> #REF!
A17: =Working!#REF! -> #REF!
A19: ='Format - Resident investors'!A19 -> Re: Notice of 15th Drawdown for XYZ FUND ('the Fund')
A21: Dear Investor,
A23: The undersigned refers to the Contribution Agreement dated September 29, 2025, (hereinafter referred to as the “Contribution Agreement”), and hereby gives you notice, pursuant to the Contribution Agreement, that the undersigned hereby requests the Drawdown, and in that connection sets forth below the information relating to such Drawdown as required under the Contribution Agreement.
A25: A summary of your capital commitment and contributions is given below:
A27: ='Format - Resident investors'!A27 -> Capital commitment to XYZ FUND (INR) | B27: ='Format - Resident investors'!B27 -> Capital contributed till date (INR) | C27: ='Format - Resident investors'!C27 -> Capital contribution pursuant to the 15th Drawdown (INR) | D27: Total capital contribution pursuant to the 15th Drawdown (INR) | E27: ='Format - Resident investors'!E27 -> % of the Capital commitment drawn down till date
A28: =Working!#REF! -> #REF! | B28: =Working!#REF! -> #REF! | C28: =Working!#REF! -> #REF! | D28: =Working!#REF! -> #REF! | E28: =Working!#REF! -> #REF!
A30: ='Format - Resident investors'!A30 -> The capital contribution for the current Drawdown will be applied towards portfolio investment in ABC Private Limited, Management Fees for the period 1st July 2026 to 30th September 2026 and Fund expenses.
A32: ='Format - Resident investors'!A31 -> The payment towards capital contribution for the 15th drawdown is to be made in the bank account of XYZ FUND within 15 Business Days from the date of issue of this Drawdown Notice i.e. on or before 30 June 2026
A35: Please instruct the remitting bank to transfer funds by wire transfer to the bank as mentioned below.
A37: Amount to be remitted (INR) | B37: =D28 -> #REF!
A38: Name of account holder | B38: XYZ FUND
A39: Bank Name & Branch
A40: Account type
A41: Account number
A42: IFSC Code
A43: SWIFT address
B49: =B3 -> CLIENT NAME AND ADDRESS
A55: Due to KYC norms being applicable for such investments, it is requested that the NEFT/RTGS instruction be issued from your designated bank account. Payment from third party accounts cannot be accepted.
A58: Once the payment is done, kindly inform us on our email id abc@gmail.com, the following details of your remittance as under:
A59: 1. Name of remitting bank and branch
A60: 2. Date of Remittance
A61: 3. Amount remitted
A62: 4. UTR No.
A64: Thank you in advance for your co-operation and attention to this matter.
A66: Yours truly,
A67: ='Format - Final close Employee'!A62 -> For ___________________LLP (On behalf of XYZ FUND)
A70: ='Format - Final close Employee'!A65 -> Sd/- Designated Partner
